Workbook

Sheet Cover Page
A4: =TODAY() -> 45776
A6: Semantic Web for Valuation
A7: Deliverable 1: Approximation Valuation Model for Mobile Apps
A8: BY
A9: Chen Li, Prachi Mishra, Yilin Xie

Sheet Assumption Table
A1: Assumption Table
B3: KPIs Assumptions
B4: Organic Downloads
B5: Mean | C5: 10000
B6: Stdev | C6: 1000
B7: Growth rate | C7: 0.02
B8: Paid Downloads*via marketing
B9: Mean | C9: 5000
B10: Stdev | C10: 100
B11: Growth rate | C11: 0.02
B12: Retention Rate
B13: Mean | C13: 0.5
B14: Stdev | C14: 0.1
B16: Revenue Assumptions
B17: 1.Licensing
B18: Price of the App | C18: 1.99
B20: 2.Subscription
C21: average revenue per user per month | D21: Conversion Rate(Mean) | E21: Conversion Rate(Stdev)
B22: Monthly plan | C22: 10.99 | D22: 0.3 | E22: 0.1
B23: Annual plan | C23: 8.33 | D23: 0.3 | E23: 0.1
B24: No plan | C24: 10.99 | D24: 0 | E24: 0
B26: 3. In-app purchase
C27: Price | D27: Conversion Rate(Mean) | E27: Conversion Rate(Stdev) | F27: Average repeated times
B28: item 1 - Pricing | C28: 4.99 | D28: 0.4 | E28: 0.1 | F28: 1.5
B29: item 2 - Pricing | C29: 9.9 | D29: 0.3 | E29: 0.1 | F29: 1
B30: item 3 - Pricing | C30: 19.99 | D30: 0.2 | E30: 0.1 | F30: 2
B31: item 4 - Pricing | C31: 29.99 | D31: 0.1 | E31: 0.1 | F31: 1
B33: 4. Advertisement
B34: Impressions | D34: Conversion rate (Mean) | E34: Conversion rate (Std Dev)
B35: Mean | C35: 10000 | D35: 0.2 | E35: 0.1
B36: Stdev | C36: 1000
B37: Click-Through Rate (CTR)
B38: Mean | C38: 0.25
B39: Stdev | C39: 0.005
B40: Revenue/Cost per Click (CPC) | C40: 0.7
B42: 5. Commission
B43: Transactions | C43: # of transactions
B44: Mean | C44: 100
B45: Stdev | C45: 0.1
B46: Growth rate | C46: 0.05
...

Sheet Projection Model
A1: Projection Model
B2: 1 | C2: 2 | D2: 3 | E2: 4 | F2: 5 | G2: 6 | H2: 7 | I2: 8 | J2: 9 | K2: 10 | L2: 11 | M2: 12 | N2: 13 | O2: 14 | P2: 15 | Q2: 16 | R2: 17 | S2: 18 | T2: 19 | U2: 20 | V2: 21 | W2: 22 | X2: 23 | Y2: 24 | Z2: 25 | AA2: 26 | AB2: 27 | AC2: 28 | AD2: 29 | AE2: 30 | AF2: 31 | AG2: 32 | AH2: 33 | AI2: 34 | AJ2: 35 | AK2: 36 | AL2: 37 | AM2: 38 | AN2: 39 | AO2: 40 | AP2: 41 | AQ2: 42 | AR2: 43 | AS2: 44 | AT2: 45 | AU2: 46 | AV2: 47 | AW2: 48 | AX2: 49 | AY2: 50 | AZ2: 51 | BA2: 52 | BB2: 53 | BC2: 54 | BD2: 55 | BE2: 56 | BF2: 57 | BG2: 58 | BH2: 59 | BI2: 60 | BK2: 1 | BL2: 2 | BM2: 3 | BN2: 4 | BO2: 5
A3: KPIs Schedule | BJ3: =A3 -> KPIs Schedule
B4: 1 | C4: =B4+1 -> 2 | D4: =C4+1 -> 3 | E4: =D4+1 -> 4 | F4: =E4+1 -> 5 | G4: =F4+1 -> 6 | H4: =G4+1 -> 7 | I4: =H4+1 -> 8 | J4: =I4+1 -> 9 | ... BI4: =BH4+1 -> 60 | BK4: 1 | BL4: =BK4+1 -> 2 | BM4: =BL4+1 -> 3 | BN4: =BM4+1 -> 4 | BO4: =BN4+1 -> 5
A5: Organic Downloads | B5: =ROUND(MAX(0,NORMINV(RAND(), B6, 'Assumption Table'!$C$6)),0) -> 11111 | C5: =ROUND(MAX(0,NORMINV(RAND(), C6, 'Assumption Table'!$C$6)),0) -> 10631 | D5: =ROUND(MAX(0,NORMINV(RAND(), D6, 'Assumption Table'!$C$6)),0) -> 9960 | E5: =ROUND(MAX(0,NORMINV(RAND(), E6, 'Assumption Table'!$C$6)),0) -> 10410 | F5: =ROUND(MAX(0,NORMINV(RAND(), F6, 'Assumption Table'!$C$6)),0) -> 9486 | G5: =ROUND(MAX(0,NORMINV(RAND(), G6, 'Assumption Table'!$C$6)),0) -> 10687 | H5: =ROUND(MAX(0,NORMINV(RAND(), H6, 'Assumption Table'!$C$6)),0) -> 12027 | I5: =ROUND(MAX(0,NORMINV(RAND(), I6, 'Assumption Table'!$C$6)),0) -> 10157 | ... BI5: =ROUND(MAX(0,NORMINV(RAND(), BI6, 'Assumption Table'!$C$6)),0) -> 29639 | BJ5: =A5 -> Organic Downloads | BK5: =SUMIFS($B5:$BI5,$B$4:$BI$4,"<=12") -> 130043 | BL5: =SUMIFS($B5:$BI5,$B$4:$BI$4,"<=24",$B$4:$BI$4,">12") -> 166099 | BM5: =SUMIFS($B5:$BI5,$B$4:$BI$4,"<=36",$B$4:$BI$4,">24") -> 211871 | BN5: =SUMIFS($B5:$BI5,$B$4:$BI$4,"<=48",$B$4:$BI$4,">36") -> 272189 | BO5: =SUMIFS($B5:$BI5,$B$4:$BI$4,"<=60",$B$4:$BI$4,">48") -> 351801
A6: Mean | B6: ='Assumption Table'!C5 -> 10000 | C6: =ROUND(B6*(1+'Assumption Table'!$C$7),0) -> 10200 | D6: =ROUND(C6*(1+'Assumption Table'!$C$7),0) -> 10404 | E6: =ROUND(D6*(1+'Assumption Table'!$C$7),0) -> 10612 | F6: =ROUND(E6*(1+'Assumption Table'!$C$7),0) -> 10824 | G6: =ROUND(F6*(1+'Assumption Table'!$C$7),0) -> 11040 | H6: =ROUND(G6*(1+'Assumption Table'!$C$7),0) -> 11261 | I6: =ROUND(H6*(1+'Assumption Table'!$C$7),0) -> 11486 | J6: =ROUND(I6*(1+'Assumption Table'!$C$7),0) -> 11716 | ... BI6: =ROUND(BH6*(1+'Assumption Table'!$C$7),0) -> 32164
A7: Paid Downloads | B7: =ROUND(MAX(0,NORMINV(RAND(), B8, 'Assumption Table'!$C$10)),0) -> 5017 | C7: =ROUND(MAX(0,NORMINV(RAND(), C8, 'Assumption Table'!$C$10)),0) -> 4922 | D7: =ROUND(MAX(0,NORMINV(RAND(), D8, 'Assumption Table'!$C$10)),0) -> 5195 | E7: =ROUND(MAX(0,NORMINV(RAND(), E8, 'Assumption Table'!$C$10)),0) -> 5210 | F7: =ROUND(MAX(0,NORMINV(RAND(), F8, 'Assumption Table'!$C$10)),0) -> 5384 | G7: =ROUND(MAX(0,NORMINV(RAND(), G8, 'Assumption Table'!$C$10)),0) -> 5426 | H7: =ROUND(MAX(0,NORMINV(RAND(), H8, 'Assumption Table'!$C$10)),0) -> 5545 | I7: =ROUND(MAX(0,NORMINV(RAND(), I8, 'Assumption Table'!$C$10)),0) -> 5740 | ... BI7: =ROUND(MAX(0,NORMINV(RAND(), BI8, 'Assumption Table'!$C$10)),0) -> 16135 | BJ7: =A7 -> Paid Downloads | BK7: =SUMIFS($B7:$BI7,$B$4:$BI$4,"<=12") -> 66699 | BL7: =SUMIFS($B7:$BI7,$B$4:$BI$4,"<=24",$B$4:$BI$4,">12") -> 85321 | BM7: =SUMIFS($B7:$BI7,$B$4:$BI$4,"<=36",$B$4:$BI$4,">24") -> 108341 | BN7: =SUMIFS($B7:$BI7,$B$4:$BI$4,"<=48",$B$4:$BI$4,">36") -> 136488 | BO7: =SUMIFS($B7:$BI7,$B$4:$BI$4,"<=60",$B$4:$BI$4,">48") -> 173450
A8: Mean | B8: ='Assumption Table'!C9 -> 5000 | C8: =ROUND(B8*(1+'Assumption Table'!$C$11),0) -> 5100 | D8: =ROUND(C8*(1+'Assumption Table'!$C$11),0) -> 5202 | E8: =ROUND(D8*(1+'Assumption Table'!$C$11),0) -> 5306 | F8: =ROUND(E8*(1+'Assumption Table'!$C$11),0) -> 5412 | G8: =ROUND(F8*(1+'Assumption Table'!$C$11),0) -> 5520 | H8: =ROUND(G8*(1+'Assumption Table'!$C$11),0) -> 5630 | I8: =ROUND(H8*(1+'Assumption Table'!$C$11),0) -> 5743 | J8: =ROUND(I8*(1+'Assumption Table'!$C$11),0) -> 5858 | ... BI8: =ROUND(BH8*(1+'Assumption Table'!$C$11),0) -> 16087
A9: Total New Downloads | B9: =SUM(B5,B7) -> 16128 | C9: =SUM(C5,C7) -> 15553 | D9: =SUM(D5,D7) -> 15155 | E9: =SUM(E5,E7) -> 15620 | F9: =SUM(F5,F7) -> 14870 | G9: =SUM(G5,G7) -> 16113 | H9: =SUM(H5,H7) -> 17572 | I9: =SUM(I5,I7) -> 15897 | ... BI9: =SUM(BI5,BI7) -> 45774 | BJ9: =A9 -> Total New Downloads | BK9: =SUMIFS($B9:$BI9,$B$4:$BI$4,"<=12") -> 196742 | BL9: =SUMIFS($B9:$BI9,$B$4:$BI$4,"<=24",$B$4:$BI$4,">12") -> 251420 | BM9: =SUMIFS($B9:$BI9,$B$4:$BI$4,"<=36",$B$4:$BI$4,">24") -> 320212 | BN9: =SUMIFS($B9:$BI9,$B$4:$BI$4,"<=48",$B$4:$BI$4,">36") -> 408677 | BO9: =SUMIFS($B9:$BI9,$B$4:$BI$4,"<=60",$B$4:$BI$4,">48") -> 525251
A10: Cumulative Downloads | B10: =B9 -> 16128 | C10: =B10+C9 -> 31681 | D10: =C10+D9 -> 46836 | E10: =D10+E9 -> 62456 | F10: =E10+F9 -> 77326 | G10: =F10+G9 -> 93439 | H10: =G10+H9 -> 111011 | I10: =H10+I9 -> 126908 | J10: =I10+J9 -> 143876 | ... BI10: =BH10+BI9 -> 1702302 | BJ10: =A10 -> Cumulative Downloads | BK10: =SUMIFS($B10:$BI10,$B$4:$BI$4,"=12") -> 196742 | BL10: =SUMIFS($B10:$BI10,$B$4:$BI$4,"=24") -> 448162 | BM10: =SUMIFS($B10:$BI10,$B$4:$BI$4,"=36") -> 768374 | BN10: =SUMIFS($B10:$BI10,$B$4:$BI$4,"=48") -> 1177051 | BO10: =SUMIFS($B10:$BI10,$B$4:$BI$4,"=60") -> 1702302
BJ11: =A11 -> 0
A12: Retention rate | B12: =MAX(0, MIN(1, NORMINV(RAND(), 'Assumption Table'!$C$13, 'Assumption Table'!$C$14))) -> 0.47590206 | C12: =MAX(0, MIN(1, NORMINV(RAND(), 'Assumption Table'!$C$13, 'Assumption Table'!$C$14))) -> 0.53473812 | D12: =MAX(0, MIN(1, NORMINV(RAND(), 'Assumption Table'!$C$13, 'Assumption Table'!$C$14))) -> 0.56285626 | E12: =MAX(0, MIN(1, NORMINV(RAND(), 'Assumption Table'!$C$13, 'Assumption Table'!$C$14))) -> 0.40676654 | F12: =MAX(0, MIN(1, NORMINV(RAND(), 'Assumption Table'!$C$13, 'Assumption Table'!$C$14))) -> 0.54053542 | G12: =MAX(0, MIN(1, NORMINV(RAND(), 'Assumption Table'!$C$13, 'Assumption Table'!$C$14))) -> 0.51296365 | H12: =MAX(0, MIN(1, NORMINV(RAND(), 'Assumption Table'!$C$13, 'Assumption Table'!$C$14))) -> 0.48736059 | I12: =MAX(0, MIN(1, NORMINV(RAND(), 'Assumption Table'!$C$13, 'Assumption Table'!$C$14))) -> 0.52229978 | ... BI12: =MAX(0, MIN(1, NORMINV(RAND(), 'Assumption Table'!$C$13, 'Assumption Table'!$C$14))) -> 0.57144063
A13: Churn rate | B13: =1-B12 -> 0.52409794 | C13: =1-C12 -> 0.46526188 | D13: =1-D12 -> 0.43714374 | E13: =1-E12 -> 0.59323346 | F13: =1-F12 -> 0.45946458 | G13: =1-G12 -> 0.48703635 | H13: =1-H12 -> 0.51263941 | I13: =1-I12 -> 0.47770022 | ... BI13: =1-BI12 -> 0.42855937
A14: Active Users | B14: =ROUND(B10*B12,0) -> 7675 | C14: =ROUND(C10*C12,0) -> 16941 | D14: =ROUND(D10*D12,0) -> 26362 | E14: =ROUND(E10*E12,0) -> 25405 | F14: =ROUND(F10*F12,0) -> 41797 | G14: =ROUND(G10*G12,0) -> 47931 | H14: =ROUND(H10*H12,0) -> 54102 | I14: =ROUND(I10*I12,0) -> 66284 | ... BI14: =ROUND(BI10*BI12,0) -> 972765 | BJ14: =A14 -> Active Users | BK14: =SUMIFS($B14:$BI14,$B$4:$BI$4,"=12") -> 76633 | BL14: =SUMIFS($B14:$BI14,$B$4:$BI$4,"=24") -> 215639 | BM14: =SUMIFS($B14:$BI14,$B$4:$BI$4,"=36") -> 300273 | BN14: =SUMIFS($B14:$BI14,$B$4:$BI$4,"=48") -> 446275 | BO14: =SUMIFS($B14:$BI14,$B$4:$BI$4,"=60") -> 972765
BJ15: =A15 -> 0
A16: Revenue Schedule | BJ16: =A16 -> Revenue Schedule
B17: 1 | C17: 2 | D17: 3 | E17: 4 | F17: 5 | G17: 6 | H17: 7 | I17: 8 | J17: 9 | K17: 10 | L17: 11 | M17: 12 | N17: 13 | O17: 14 | P17: 15 | Q17: 16 | R17: 17 | S17: 18 | T17: 19 | U17: 20 | V17: 21 | W17: 22 | X17: 23 | Y17: 24 | Z17: 25 | AA17: 26 | AB17: 27 | AC17: 28 | AD17: 29 | AE17: 30 | AF17: 31 | AG17: 32 | AH17: 33 | AI17: 34 | AJ17: 35 | AK17: 36 | AL17: 37 | AM17: 38 | AN17: 39 | AO17: 40 | AP17: 41 | AQ17: 42 | AR17: 43 | AS17: 44 | AT17: 45 | AU17: 46 | AV17: 47 | AW17: 48 | AX17: 49 | AY17: 50 | AZ17: 51 | BA17: 52 | BB17: 53 | BC17: 54 | BD17: 55 | BE17: 56 | BF17: 57 | BG17: 58 | BH17: 59 | BI17: 60 | BJ17: =A17 -> 0 | BK17: 1 | BL17: 2 | BM17: 3 | BN17: 4 | BO17: 5
A18: ='Assumption Table'!B17 -> 1.Licensing | BJ18: =A18 -> 1.Licensing
A19: Revenue from Licensing | B19: ='Assumption Table'!$C$18*B9 -> 32094.72 | C19: ='Assumption Table'!$C$18*C9 -> 30950.47 | D19: ='Assumption Table'!$C$18*D9 -> 30158.45 | E19: ='Assumption Table'!$C$18*E9 -> 31083.8 | F19: ='Assumption Table'!$C$18*F9 -> 29591.3 | G19: ='Assumption Table'!$C$18*G9 -> 32064.87 | H19: ='Assumption Table'!$C$18*H9 -> 34968.28 | I19: ='Assumption Table'!$C$18*I9 -> 31635.03 | ... BI19: ='Assumption Table'!$C$18*BI9 -> 91090.26 | BJ19: =A19 -> Revenue from Licensing | BK19: =SUMIFS($B19:$BI19,$B$4:$BI$4,"<=12") -> 391516.58 | BL19: =SUMIFS($B19:$BI19,$B$4:$BI$4,"<=24",$B$4:$BI$4,">12") -> 500325.8 | BM19: =SUMIFS($B19:$BI19,$B$4:$BI$4,"<=36",$B$4:$BI$4,">24") -> 637221.88 | BN19: =SUMIFS($B19:$BI19,$B$4:$BI$4,"<=48",$B$4:$BI$4,">36") -> 813267.23 | BO19: =SUMIFS($B19:$BI19,$B$4:$BI$4,"<=60",$B$4:$BI$4,">48") -> 1045249.5
BJ20: =A20 -> 0
A21: ='Assumption Table'!B20 -> 2.Subscription | BJ21: =A21 -> 2.Subscription
A22: Monthly Plan | B22: ='Assumption Table'!$C$22*B23*B14 -> 35411.567 | C22: ='Assumption Table'!$C$22*C23*C14 -> 70246.79 | D22: ='Assumption Table'!$C$22*D23*D14 -> 124901.54 | E22: ='Assumption Table'!$C$22*E23*E14 -> 114484.66 | F22: ='Assumption Table'!$C$22*F23*F14 -> 105018.28 | G22: ='Assumption Table'!$C$22*G23*G14 -> 144524.11 | H22: ='Assumption Table'!$C$22*H23*H14 -> 136815.63 | I22: ='Assumption Table'!$C$22*I23*I14 -> 176908.12 | ... BI22: ='Assumption Table'!$C$22*BI23*BI14 -> 3306877.5 | BJ22: =A22 -> Monthly Plan | BK22: =SUMIFS($B22:$BI22,$B$4:$BI$4,"<=12") -> 2143474.5 | BL22: =SUMIFS($B22:$BI22,$B$4:$BI$4,"<=24",$B$4:$BI$4,">12") -> 7044753.1 | BM22: =SUMIFS($B22:$BI22,$B$4:$BI$4,"<=36",$B$4:$BI$4,">24") -> 12398382 | BN22: =SUMIFS($B22:$BI22,$B$4:$BI$4,"<=48",$B$4:$BI$4,">36") -> 16977451 | BO22: =SUMIFS($B22:$BI22,$B$4:$BI$4,"<=60",$B$4:$BI$4,">48") -> 31668971
A23: Conversion Rate | B23: =MAX(0,MIN(1,NORMINV(RAND(),'Assumption Table'!$D$22,'Assumption Table'!$E$22))) -> 0.41982575 | C23: =MAX(0,MIN(1,NORMINV(RAND(),'Assumption Table'!$D$22,'Assumption Table'!$E$22))) -> 0.37730256 | D23: =MAX(0,MIN(1,NORMINV(RAND(),'Assumption Table'!$D$22,'Assumption Table'!$E$22))) -> 0.43111362 | E23: =MAX(0,MIN(1,NORMINV(RAND(),'Assumption Table'!$D$22,'Assumption Table'!$E$22))) -> 0.41004396 | F23: =MAX(0,MIN(1,NORMINV(RAND(),'Assumption Table'!$D$22,'Assumption Table'!$E$22))) -> 0.22862415 | G23: =MAX(0,MIN(1,NORMINV(RAND(),'Assumption Table'!$D$22,'Assumption Table'!$E$22))) -> 0.27436336 | H23: =MAX(0,MIN(1,NORMINV(RAND(),'Assumption Table'!$D$22,'Assumption Table'!$E$22))) -> 0.23010429 | I23: =MAX(0,MIN(1,NORMINV(RAND(),'Assumption Table'!$D$22,'Assumption Table'!$E$22))) -> 0.24285182 | ... BI23: =MAX(0,MIN(1,NORMINV(RAND(),'Assumption Table'!$D$22,'Assumption Table'!$E$22))) -> 0.30932319
A24: Annual Plan | B24: ='Assumption Table'!$C$23*B25*B14 -> 19571.066 | C24: ='Assumption Table'!$C$23*C25*C14 -> 52451.155 | D24: ='Assumption Table'!$C$23*D25*D14 -> 56893.433 | E24: ='Assumption Table'!$C$23*E25*E14 -> 54574.341 | F24: ='Assumption Table'!$C$23*F25*F14 -> 26446.288 | G24: ='Assumption Table'!$C$23*G25*G14 -> 183040.24 | H24: ='Assumption Table'!$C$23*H25*H14 -> 179484.11 | I24: ='Assumption Table'!$C$23*I25*I14 -> 196886.43 | ... BI24: ='Assumption Table'!$C$23*BI25*BI14 -> 1703972.1 | BJ24: =A24 -> Annual Plan | BK24: =SUMIFS($B24:$BI24,$B$4:$BI$4,"<=12") -> 1766820.1 | BL24: =SUMIFS($B24:$BI24,$B$4:$BI$4,"<=24",$B$4:$BI$4,">12") -> 3907849 | BM24: =SUMIFS($B24:$BI24,$B$4:$BI$4,"<=36",$B$4:$BI$4,">24") -> 9464077.2 | BN24: =SUMIFS($B24:$BI24,$B$4:$BI$4,"<=48",$B$4:$BI$4,">36") -> 17213742 | BO24: =SUMIFS($B24:$BI24,$B$4:$BI$4,"<=60",$B$4:$BI$4,">48") -> 22524934
A25: Conversion Rate | B25: =MAX(0,MIN(1-B23,NORMINV(RAND(),'Assumption Table'!$D$23,'Assumption Table'!$E$23))) -> 0.30611957 | C25: =MAX(0,MIN(1-C23,NORMINV(RAND(),'Assumption Table'!$D$23,'Assumption Table'!$E$23))) -> 0.37168156 | D25: =MAX(0,MIN(1-D23,NORMINV(RAND(),'Assumption Table'!$D$23,'Assumption Table'!$E$23))) -> 0.25908292 | E25: =MAX(0,MIN(1-E23,NORMINV(RAND(),'Assumption Table'!$D$23,'Assumption Table'!$E$23))) -> 0.25788394 | F25: =MAX(0,MIN(1-F23,NORMINV(RAND(),'Assumption Table'!$D$23,'Assumption Table'!$E$23))) -> 0.075958192 | G25: =MAX(0,MIN(1-G23,NORMINV(RAND(),'Assumption Table'!$D$23,'Assumption Table'!$E$23))) -> 0.45844272 | H25: =MAX(0,MIN(1-H23,NORMINV(RAND(),'Assumption Table'!$D$23,'Assumption Table'!$E$23))) -> 0.39826092 | I25: =MAX(0,MIN(1-I23,NORMINV(RAND(),'Assumption Table'!$D$23,'Assumption Table'!$E$23))) -> 0.35658418 | ... BI25: =MAX(0,MIN(1-BI23,NORMINV(RAND(),'Assumption Table'!$D$23,'Assumption Table'!$E$23))) -> 0.21028561
A26: Total revenue from Subscription | B26: =SUM(B22,B24) -> 54982.634 | C26: =SUM(C22,C24) -> 122697.94 | D26: =SUM(D22,D24) -> 181794.97 | E26: =SUM(E22,E24) -> 169059.01 | F26: =SUM(F22,F24) -> 131464.57 | G26: =SUM(G22,G24) -> 327564.35 | H26: =SUM(H22,H24) -> 316299.75 | I26: =SUM(I22,I24) -> 373794.54 | ... BI26: =SUM(BI22,BI24) -> 5010849.7 | BJ26: =A26 -> Total revenue from Subscription | BK26: =SUMIFS($B26:$BI26,$B$4:$BI$4,"<=12") -> 3910294.6 | BL26: =SUMIFS($B26:$BI26,$B$4:$BI$4,"<=24",$B$4:$BI$4,">12") -> 10952602 | BM26: =SUMIFS($B26:$BI26,$B$4:$BI$4,"<=36",$B$4:$BI$4,">24") -> 21862460 | BN26: =SUMIFS($B26:$BI26,$B$4:$BI$4,"<=48",$B$4:$BI$4,">36") -> 34191194 | BO26: =SUMIFS($B26:$BI26,$B$4:$BI$4,"<=60",$B$4:$BI$4,">48") -> 54193905
BJ27: =A27 -> 0
A28: ='Assumption Table'!B26 -> 3. In-app purchase | BJ28: =A28 -> 3. In-app purchase
A29: item 1 | B29: ='Assumption Table'!$C$28*B30*B$14*'Assumption Table'!$F$28 -> 23202.648 | C29: ='Assumption Table'!$C$28*C30*C$14*'Assumption Table'!$F$28 -> 56264.674 | D29: ='Assumption Table'!$C$28*D30*D$14*'Assumption Table'!$F$28 -> 54019.767 | E29: ='Assumption Table'!$C$28*E30*E$14*'Assumption Table'!$F$28 -> 65148.401 | F29: ='Assumption Table'!$C$28*F30*F$14*'Assumption Table'!$F$28 -> 104741.91 | G29: ='Assumption Table'!$C$28*G30*G$14*'Assumption Table'!$F$28 -> 184419.28 | H29: ='Assumption Table'!$C$28*H30*H$14*'Assumption Table'!$F$28 -> 131592.46 | I29: ='Assumption Table'!$C$28*I30*I$14*'Assumption Table'!$F$28 -> 206292.52 | ... BI29: ='Assumption Table'!$C$28*BI30*BI$14*'Assumption Table'!$F$28 -> 2777066.2 | BJ29: =A29 -> item 1 | BK29: =SUMIFS($B29:$BI29,$B$4:$BI$4,"<=12") -> 1926243 | BL29: =SUMIFS($B29:$BI29,$B$4:$BI$4,"<=24",$B$4:$BI$4,">12") -> 7023309.1 | BM29: =SUMIFS($B29:$BI29,$B$4:$BI$4,"<=36",$B$4:$BI$4,">24") -> 11414757 | BN29: =SUMIFS($B29:$BI29,$B$4:$BI$4,"<=48",$B$4:$BI$4,">36") -> 19128234 | BO29: =SUMIFS($B29:$BI29,$B$4:$BI$4,"<=60",$B$4:$BI$4,">48") -> 26128283
A30: Conversion Rate | B30: =MAX(0,MIN(1,NORMINV(RAND(),'Assumption Table'!$D$28,'Assumption Table'!$E$28))) -> 0.40389396 | C30: =MAX(0,MIN(1,NORMINV(RAND(),'Assumption Table'!$D$28,'Assumption Table'!$E$28))) -> 0.44371586 | D30: =MAX(0,MIN(1,NORMINV(RAND(),'Assumption Table'!$D$28,'Assumption Table'!$E$28))) -> 0.27376791 | E30: =MAX(0,MIN(1,NORMINV(RAND(),'Assumption Table'!$D$28,'Assumption Table'!$E$28))) -> 0.34260426 | F30: =MAX(0,MIN(1,NORMINV(RAND(),'Assumption Table'!$D$28,'Assumption Table'!$E$28))) -> 0.33479857 | G30: =MAX(0,MIN(1,NORMINV(RAND(),'Assumption Table'!$D$28,'Assumption Table'!$E$28))) -> 0.51404131 | H30: =MAX(0,MIN(1,NORMINV(RAND(),'Assumption Table'!$D$28,'Assumption Table'!$E$28))) -> 0.32495699 | I30: =MAX(0,MIN(1,NORMINV(RAND(),'Assumption Table'!$D$28,'Assumption Table'!$E$28))) -> 0.41579854 | ... BI30: =MAX(0,MIN(1,NORMINV(RAND(),'Assumption Table'!$D$28,'Assumption Table'!$E$28))) -> 0.3814051
A31: item 2 | B31: ='Assumption Table'!$C$29*B32*B$14*'Assumption Table'!$F$29 -> 28386.906 | C31: ='Assumption Table'!$C$29*C32*C$14*'Assumption Table'!$F$29 -> 68367.121 | D31: ='Assumption Table'!$C$29*D32*D$14*'Assumption Table'!$F$29 -> 73544.401 | E31: ='Assumption Table'!$C$29*E32*E$14*'Assumption Table'!$F$29 -> 48303.884 | F31: ='Assumption Table'!$C$29*F32*F$14*'Assumption Table'!$F$29 -> 149140.49 | G31: ='Assumption Table'!$C$29*G32*G$14*'Assumption Table'!$F$29 -> 150433.91 | H31: ='Assumption Table'!$C$29*H32*H$14*'Assumption Table'!$F$29 -> 68155.091 | I31: ='Assumption Table'!$C$29*I32*I$14*'Assumption Table'!$F$29 -> 200899.75 | ... BI31: ='Assumption Table'!$C$29*BI32*BI$14*'Assumption Table'!$F$29 -> 2794379 | BJ31: =A31 -> item 2 | BK31: =SUMIFS($B31:$BI31,$B$4:$BI$4,"<=12") -> 1964295.3 | BL31: =SUMIFS($B31:$BI31,$B$4:$BI$4,"<=24",$B$4:$BI$4,">12") -> 5485108.5 | BM31: =SUMIFS($B31:$BI31,$B$4:$BI$4,"<=36",$B$4:$BI$4,">24") -> 10263633 | BN31: =SUMIFS($B31:$BI31,$B$4:$BI$4,"<=48",$B$4:$BI$4,">36") -> 17067420 | BO31: =SUMIFS($B31:$BI31,$B$4:$BI$4,"<=60",$B$4:$BI$4,">48") -> 26350747
A32: Conversion Rate | B32: =MAX(0,MIN(1,NORMINV(RAND(),'Assumption Table'!$D$29,'Assumption Table'!$E$29))) -> 0.37359794 | C32: =MAX(0,MIN(1,NORMINV(RAND(),'Assumption Table'!$D$29,'Assumption Table'!$E$29))) -> 0.40763649 | D32: =MAX(0,MIN(1,NORMINV(RAND(),'Assumption Table'!$D$29,'Assumption Table'!$E$29))) -> 0.28179681 | E32: =MAX(0,MIN(1,NORMINV(RAND(),'Assumption Table'!$D$29,'Assumption Table'!$E$29))) -> 0.1920559 | F32: =MAX(0,MIN(1,NORMINV(RAND(),'Assumption Table'!$D$29,'Assumption Table'!$E$29))) -> 0.3604253 | G32: =MAX(0,MIN(1,NORMINV(RAND(),'Assumption Table'!$D$29,'Assumption Table'!$E$29))) -> 0.3170254 | H32: =MAX(0,MIN(1,NORMINV(RAND(),'Assumption Table'!$D$29,'Assumption Table'!$E$29))) -> 0.12724766 | I32: =MAX(0,MIN(1,NORMINV(RAND(),'Assumption Table'!$D$29,'Assumption Table'!$E$29))) -> 0.30615086 | ... BI32: =MAX(0,MIN(1,NORMINV(RAND(),'Assumption Table'!$D$29,'Assumption Table'!$E$29))) -> 0.2901631
A33: item 3 | B33: ='Assumption Table'!$C$30*B34*B$14 -> 38679.598 | C33: ='Assumption Table'!$C$30*C34*C$14 -> 0 | D33: ='Assumption Table'!$C$30*D34*D$14 -> 150023.03 | E33: ='Assumption Table'!$C$30*E34*E$14 -> 103642.48 | F33: ='Assumption Table'!$C$30*F34*F$14 -> 79310.653 | G33: ='Assumption Table'!$C$30*G34*G$14 -> 163353.18 | H33: ='Assumption Table'!$C$30*H34*H$14 -> 295280.89 | I33: ='Assumption Table'!$C$30*I34*I$14 -> 369793.17 | ... BI33: ='Assumption Table'!$C$30*BI34*BI$14 -> 3281726.4 | BJ33: =A33 -> item 3 | BK33: =SUMIFS($B33:$BI33,$B$4:$BI$4,"<=12") -> 2588651.7 | BL33: =SUMIFS($B33:$BI33,$B$4:$BI$4,"<=24",$B$4:$BI$4,">12") -> 11734036 | BM33: =SUMIFS($B33:$BI33,$B$4:$BI$4,"<=36",$B$4:$BI$4,">24") -> 16511338 | BN33: =SUMIFS($B33:$BI33,$B$4:$BI$4,"<=48",$B$4:$BI$4,">36") -> 20681451 | BO33: =SUMIFS($B33:$BI33,$B$4:$BI$4,"<=60",$B$4:$BI$4,">48") -> 30925516
A34: Conversion Rate | B34: =MAX(0,MIN(1,NORMINV(RAND(),'Assumption Table'!$D$30,'Assumption Table'!$E$30))) -> 0.25211041 | C34: =MAX(0,MIN(1,NORMINV(RAND(),'Assumption Table'!$D$30,'Assumption Table'!$E$30))) -> 0 | D34: =MAX(0,MIN(1,NORMINV(RAND(),'Assumption Table'!$D$30,'Assumption Table'!$E$30))) -> 0.28468645 | E34: =MAX(0,MIN(1,NORMINV(RAND(),'Assumption Table'!$D$30,'Assumption Table'!$E$30))) -> 0.20408251 | F34: =MAX(0,MIN(1,NORMINV(RAND(),'Assumption Table'!$D$30,'Assumption Table'!$E$30))) -> 0.094923474 | G34: =MAX(0,MIN(1,NORMINV(RAND(),'Assumption Table'!$D$30,'Assumption Table'!$E$30))) -> 0.17048977 | H34: =MAX(0,MIN(1,NORMINV(RAND(),'Assumption Table'!$D$30,'Assumption Table'!$E$30))) -> 0.27302928 | I34: =MAX(0,MIN(1,NORMINV(RAND(),'Assumption Table'!$D$30,'Assumption Table'!$E$30))) -> 0.27908557 | ... BI34: =MAX(0,MIN(1,NORMINV(RAND(),'Assumption Table'!$D$30,'Assumption Table'!$E$30))) -> 0.16876471
A35: item 4 | B35: ='Assumption Table'!$C$31*B36*B$14 -> 993.92139 | C35: ='Assumption Table'!$C$31*C36*C$14 -> 69548.383 | D35: ='Assumption Table'!$C$31*D36*D$14 -> 193458.3 | E35: ='Assumption Table'!$C$31*E36*E$14 -> 61041.594 | F35: ='Assumption Table'!$C$31*F36*F$14 -> 148924.75 | G35: ='Assumption Table'!$C$31*G36*G$14 -> 247973.61 | H35: ='Assumption Table'!$C$31*H36*H$14 -> 217977.47 | I35: ='Assumption Table'!$C$31*I36*I$14 -> 307276.03 | ... BI35: ='Assumption Table'!$C$31*BI36*BI$14 -> 5179589.5 | BJ35: =A35 -> item 4 | BK35: =SUMIFS($B35:$BI35,$B$4:$BI$4,"<=12") -> 2538930.6 | BL35: =SUMIFS($B35:$BI35,$B$4:$BI$4,"<=24",$B$4:$BI$4,">12") -> 7406410 | BM35: =SUMIFS($B35:$BI35,$B$4:$BI$4,"<=36",$B$4:$BI$4,">24") -> 14996446 | BN35: =SUMIFS($B35:$BI35,$B$4:$BI$4,"<=48",$B$4:$BI$4,">36") -> 17309233 | BO35: =SUMIFS($B35:$BI35,$B$4:$BI$4,"<=60",$B$4:$BI$4,">48") -> 37442038
A36: Conversion Rate | B36: =MAX(0,MIN(1,NORMINV(RAND(),'Assumption Table'!$D$31,'Assumption Table'!$E$31))) -> 0.0043181447 | C36: =MAX(0,MIN(1,NORMINV(RAND(),'Assumption Table'!$D$31,'Assumption Table'!$E$31))) -> 0.13688994 | D36: =MAX(0,MIN(1,NORMINV(RAND(),'Assumption Table'!$D$31,'Assumption Table'!$E$31))) -> 0.2446992 | E36: =MAX(0,MIN(1,NORMINV(RAND(),'Assumption Table'!$D$31,'Assumption Table'!$E$31))) -> 0.080118018 | F36: =MAX(0,MIN(1,NORMINV(RAND(),'Assumption Table'!$D$31,'Assumption Table'!$E$31))) -> 0.1188079 | G36: =MAX(0,MIN(1,NORMINV(RAND(),'Assumption Table'!$D$31,'Assumption Table'!$E$31))) -> 0.1725093 | H36: =MAX(0,MIN(1,NORMINV(RAND(),'Assumption Table'!$D$31,'Assumption Table'!$E$31))) -> 0.1343451 | I36: =MAX(0,MIN(1,NORMINV(RAND(),'Assumption Table'!$D$31,'Assumption Table'!$E$31))) -> 0.15457651 | ... BI36: =MAX(0,MIN(1,NORMINV(RAND(),'Assumption Table'!$D$31,'Assumption Table'!$E$31))) -> 0.17754602
A37: Total revenue from In app Purchase | B37: =SUM(B29,B31,B33,B35) -> 91263.073 | C37: =SUM(C29,C31,C33,C35) -> 194180.18 | D37: =SUM(D29,D31,D33,D35) -> 471045.5 | E37: =SUM(E29,E31,E33,E35) -> 278136.36 | F37: =SUM(F29,F31,F33,F35) -> 482117.82 | G37: =SUM(G29,G31,G33,G35) -> 746179.97 | H37: =SUM(H29,H31,H33,H35) -> 713005.91 | I37: =SUM(I29,I31,I33,I35) -> 1084261.5 | ... BI37: =SUM(BI29,BI31,BI33,BI35) -> 14032761 | BJ37: =A37 -> Total revenue from In app Purchase | BK37: =SUMIFS($B37:$BI37,$B$4:$BI$4,"<=12") -> 9018120.6 | BL37: =SUMIFS($B37:$BI37,$B$4:$BI$4,"<=24",$B$4:$BI$4,">12") -> 31648864 | BM37: =SUMIFS($B37:$BI37,$B$4:$BI$4,"<=36",$B$4:$BI$4,">24") -> 53186174 | BN37: =SUMIFS($B37:$BI37,$B$4:$BI$4,"<=48",$B$4:$BI$4,">36") -> 74186338 | BO37: =SUMIFS($B37:$BI37,$B$4:$BI$4,"<=60",$B$4:$BI$4,">48") -> 1.2084658e+08
BJ38: =A38 -> 0
A39: ='Assumption Table'!B33 -> 4. Advertisement | BJ39: =A39 -> 4. Advertisement
A40: Impressions | B40: =ROUND(MAX(0,NORMINV(RAND(),'Assumption Table'!$C$35,'Assumption Table'!$C$36)),0) -> 10079 | C40: =ROUND(MAX(0,NORMINV(RAND(),'Assumption Table'!$C$35,'Assumption Table'!$C$36)),0) -> 11067 | D40: =ROUND(MAX(0,NORMINV(RAND(),'Assumption Table'!$C$35,'Assumption Table'!$C$36)),0) -> 11537 | E40: =ROUND(MAX(0,NORMINV(RAND(),'Assumption Table'!$C$35,'Assumption Table'!$C$36)),0) -> 10424 | F40: =ROUND(MAX(0,NORMINV(RAND(),'Assumption Table'!$C$35,'Assumption Table'!$C$36)),0) -> 11173 | G40: =ROUND(MAX(0,NORMINV(RAND(),'Assumption Table'!$C$35,'Assumption Table'!$C$36)),0) -> 8244 | H40: =ROUND(MAX(0,NORMINV(RAND(),'Assumption Table'!$C$35,'Assumption Table'!$C$36)),0) -> 10918 | I40: =ROUND(MAX(0,NORMINV(RAND(),'Assumption Table'!$C$35,'Assumption Table'!$C$36)),0) -> 9396 | ... BI40: =ROUND(MAX(0,NORMINV(RAND(),'Assumption Table'!$C$35,'Assumption Table'!$C$36)),0) -> 10267 | BJ40: =A40 -> Impressions | BK40: =SUMIFS($B40:$BI40,$B$4:$BI$4,"<=12") -> 124553 | BL40: =SUMIFS($B40:$BI40,$B$4:$BI$4,"<=24",$B$4:$BI$4,">12") -> 121258 | BM40: =SUMIFS($B40:$BI40,$B$4:$BI$4,"<=36",$B$4:$BI$4,">24") -> 118345 | BN40: =SUMIFS($B40:$BI40,$B$4:$BI$4,"<=48",$B$4:$BI$4,">36") -> 120534 | BO40: =SUMIFS($B40:$BI40,$B$4:$BI$4,"<=60",$B$4:$BI$4,">48") -> 114405
...

Sheet Valuation Model
A1: Valuation Model
B3: Cost of Equity | C3: ='Assumption Table'!C129 -> 0.119
B4: WACC | C4: ='Assumption Table'!C139 -> 0.092666667
B5: Sustainable Long Term Growth Rate | C5: ='Assumption Table'!C142 -> 0.04 | Q5: ^If you can instead of adding cell E18 to M10 add the average from Monte Carlo Sim to M10 as the final estimated value
F6: 1 | G6: 2 | H6: 3 | I6: 4 | J6: 5
D7: In $
D9: FCF to Equity
D10: Net Income | F10: ='Projection Model'!BK220 -> 1610832.6 | G10: ='Projection Model'!BL220 -> 5492577.7 | H10: ='Projection Model'!BM220 -> 9719334.1 | I10: ='Projection Model'!BN220 -> 12252597 | J10: ='Projection Model'!BO220 -> 22109459
D11: Depreciation | F11: ='Projection Model'!BK168 -> 48624.081 | G11: ='Projection Model'!BL168 -> 156862.58 | H11: ='Projection Model'!BM168 -> 275359.19 | I11: ='Projection Model'!BN168 -> 397452.46 | J11: ='Projection Model'!BO168 -> 640851.26
D12: CAPEX | F12: =-'Projection Model'!BK122 -> -600258 | G12: =-'Projection Model'!BL122 -> -1258242.2 | H12: =-'Projection Model'!BM122 -> -4557941.5 | I12: =-'Projection Model'!BN122 -> -4137755.3 | J12: =-'Projection Model'!BO122 -> -6089031.9
D13: Changes in working capital | F13: =-'Projection Model'!BK192 -> -456810.04 | G13: =-'Projection Model'!BL192 -> -2306534.6 | H13: =-'Projection Model'!BM192 -> -2516512 | I13: =-'Projection Model'!BN192 -> -2334773.9 | J13: =-'Projection Model'!BO192 -> -5293809.7
D15: FCF to Equity (NI+Dep-Capex-chge NWC | F15: =SUM(F10:F13) -> 602388.66 | G15: =SUM(G10:G13) -> 2084663.4 | H15: =SUM(H10:H13) -> 2920239.8 | I15: =SUM(I10:I13) -> 6177519.9 | J15: =SUM(J10:J13) -> 11367469
D16: Terminal Value at end of year 5(Second Stage, Terminal Value) | J16: =J15*(1+C5)/(C3-C5) -> 1.4964769e+08
D17: Total FCF to Equity ( both first stage and second stage) | F17: =F15 -> 602388.66 | G17: =G15 -> 2084663.4 | H17: =H15 -> 2920239.8 | I17: =I15 -> 6177519.9 | J17: =J15 -> 11367469
D18: Total Equity Value | E18: {=NPV(C3,F17:J17)} -> 14706385
D19: Total number of Shares Outstanding | E19: ='Assumption Table'!C144 -> 1000000
D20: Per Share | E20: =E18/E19 -> 14.706385
D22: Total FCF to the Firm
D23: After Tax Interest Expense | F23: ='Projection Model'!BK214*(1-'Assumption Table'!$C$110) -> 153376.88 | G23: ='Projection Model'!BL214*(1-'Assumption Table'!$C$110) -> 143699.09 | H23: ='Projection Model'!BM214*(1-'Assumption Table'!$C$110) -> 134631.95 | I23: ='Projection Model'!BN214*(1-'Assumption Table'!$C$110) -> 126136.94 | J23: ='Projection Model'!BO214*(1-'Assumption Table'!$C$110) -> 118177.94
D25: Total FCF to the Firm (Total FCF Equity + After tax Interest Expense) | F25: =F15+F23 -> 755765.54 | G25: =G15+G23 -> 2228362.5 | H25: =H15+H23 -> 3054871.8 | I25: =I15+I23 -> 6303656.9 | J25: =J15+J23 -> 11485647
D26: Terminal Value at end of year 5 | J26: =J25*(1+C5)/(C4-C5) -> 2.2680518e+08
D27: Total FCF to the Firm | F27: =F25 -> 755765.54 | G27: =G25 -> 2228362.5 | H27: =H25 -> 3054871.8 | I27: =I25 -> 6303656.9 | J27: =J25+J26 -> 2.3829083e+08
D28: Enterprise Value | E28: {=NPV(C4,F27:J27)} -> 1.6231407e+08
D29: Less Total Debt | E29: ='Projection Model'!B177 -> 4972916.7
D30: Total Equity Value | E30: =E28-E29 -> 1.5734115e+08
D31: Number of Shares | E31: =E19 -> 1000000
D32: Equity Value Per Share | E32: =E30/E31 -> 157.34115
D38: Inputs | E38: Change/10% | F38: Input Change | G38: Estimated Change for Input | H38: Total Decimal Change | I38: Final Estimated Value
D39: active users per support agent | E39: 0.15319435 | F39: 0 | G39: =((F39)/0.1)*E39 -> 0 | H39: =SUM(G39:G62) -> 0 | I39: =E18*(1+H39) -> 14706385
D40: Retention rate | E40: 0.1 | F40: 0 | G40: =((F40)/0.1)*E40 -> 0
D41: item 3 pricing | E41: 0.094328771 | F41: 0 | G41: =((F41)/0.1)*E41 -> 0
D42: item 3 ART | E42: 0.0943 | F42: 0 | G42: =((F42)/0.1)*E42 -> 0
D43: Organic Downloads Mean | E43: 0.068 | F43: 0 | G43: =((F43)/0.1)*E43 -> 0
D44: Monthly conversion rate | E44: 0.0389 | F44: 0 | G44: =((F44)/0.1)*E44 -> 0
D45: Monthly Plan | E45: 0.0389 | F45: 0 | G45: =((F45)/0.1)*E45 -> 0
D46: item 1 ART | E46: 0.036 | F46: 0 | G46: =((F46)/0.1)*E46 -> 0
D47: item 4 ART | E47: 0.0354 | F47: 0 | G47: =((F47)/0.1)*E47 -> 0
D48: item 4 pricing | E48: 0.035378744 | F48: 0 | G48: =((F48)/0.1)*E48 -> 0
D49: item 1 pricing | E49: 0.035320671 | F49: 0 | G49: =((F49)/0.1)*E49 -> 0
D50: item 2 pricing | E50: 0.035038099 | F50: 0 | G50: =((F50)/0.1)*E50 -> 0
...
